<?xml version="1.0" ?>
<!-- =================================================================================== -->
<!-- |    This document was autogenerated by xacro from human-tpl.xacro                | -->
<!-- |    EDITING THIS FILE BY HAND IS NOT RECOMMENDED                                 | -->
<!-- =================================================================================== -->
<robot name="human">
  <!-- Materials -->
  <material name="yellow-skin">
    <color rgba="1 0.7 0 1"/>
  </material>
  <material name="yellow-skin-dark">
    <color rgba="0.9 0.6 0 1"/>
  </material>
  <material name="black">
    <color rgba="0 0 0 1"/>
  </material>
  <!--***********-->
  <link name="body_default">
    </link>
  <link name="waist_default">
    </link>
  <link name="torso_default">
    <visual>
      <geometry>
        <cylinder length="0.45375" radius="0.03"/>
      </geometry>
      <material name="yellow-skin"/>
      <origin rpy="-1.54 0 -1.54" xyz="0 0 -0.226875"/>
    </visual>
    <visual>
      <geometry>
        <cylinder length="0.35200000000000004" radius="0.03"/>
      </geometry>
      <material name="yellow-skin"/>
      <origin rpy="1.5707963267948966-1.54 0 -1.54" xyz="0 0 0"/>
    </visual>
    <visual>
      <geometry>
        <cylinder length="0.1872340425531915" radius="0.03"/>
      </geometry>
      <material name="yellow-skin"/>
      <origin rpy="-0.7853981633974483-1.54 0 -1.54" xyz="0 -0.066 -0.5293749999999999"/>
    </visual>
    <visual>
      <geometry>
        <cylinder length="0.1872340425531915" radius="0.03"/>
      </geometry>
      <material name="yellow-skin"/>
      <origin rpy="0.7853981633974483-1.54 0 -1.54" xyz="0 0.066 -0.5293749999999999"/>
    </visual>
    <visual>
      <geometry>
        <sphere radius="0.03"/>
      </geometry>
      <material name="yellow-skin"/>
      <origin rpy="0 0 0" xyz="0 0 -0.45375"/>
    </visual>
  </link>
  <joint name="torso_default" type="fixed">
    <parent link="waist_default"/>
    <child link="torso_default"/>
    <origin rpy="0 0 0" xyz="0 0 0.605"/>
  </joint>
  <joint name="waist_default" type="revolute">
    <axis xyz="0 1 0"/>
    <limit effort="1000" lower="-.2" upper="1." velocity="0.5"/>
    <parent link="body_default"/>
    <child link="waist_default"/>
    <origin rpy="0 0 0" xyz="0 0 0"/>
  </joint>
  <link name="r_head_default">
    </link>
  <link name="y_head_default">
    </link>
  <link name="p_head_default">
    </link>
  <link name="head_default">
    <visual>
      <geometry>
        <sphere radius="0.11"/>
      </geometry>
      <material name="yellow-skin"/>
      <origin rpy="0 0 0" xyz="-0.055 0 0"/>
    </visual>
    <!-- eyes -->
    <visual>
      <geometry>
        <sphere radius="0.022"/>
      </geometry>
      <material name="black"/>
      <origin rpy="0 0 0" xyz="0.044000000000000004 0.044 0"/>
    </visual>
    <visual>
      <geometry>
        <sphere radius="0.022"/>
      </geometry>
      <material name="black"/>
      <origin rpy="0 0 0" xyz="0.044000000000000004 -0.044 0"/>
    </visual>
  </link>
  <joint name="r_head_default" type="revolute">
    <axis xyz="1 0 0"/>
    <limit effort="1000" lower="-1." upper="1." velocity="0.5"/>
    <parent link="torso_default"/>
    <child link="r_head_default"/>
    <origin rpy="0 0 0" xyz="0 0 0.055"/>
  </joint>
  <joint name="y_head_default" type="revolute">
    <axis xyz="0 0 1"/>
    <limit effort="1000" lower="-1.4" upper="1.4" velocity="0.5"/>
    <parent link="r_head_default"/>
    <child link="y_head_default"/>
    <origin rpy="0 0 0" xyz="0 0 0"/>
  </joint>
  <joint name="p_head_default" type="revolute">
    <axis xyz="0 -1 0"/>
    <limit effort="1000" lower="-1.5" upper="1.5" velocity="0.5"/>
    <parent link="y_head_default"/>
    <child link="p_head_default"/>
    <origin rpy="0 0 0" xyz="0 0 0"/>
  </joint>
  <joint name="head_default" type="fixed">
    <parent link="p_head_default"/>
    <child link="head_default"/>
    <origin rpy="0 0 0" xyz="0.055 0 0.11"/>
  </joint>
  <link name="l_y_shoulder_default">
    <visual>
      <geometry>
        <sphere radius="0.03"/>
      </geometry>
      <material name="yellow-skin-dark"/>
      <origin rpy="0 0 0" xyz="0 0 0"/>
    </visual>
  </link>
  <joint name="l_y_shoulder_default" type="revolute">
    <axis xyz="0 0 -1"/>
    <limit effort="1000" lower="-1.7" upper="1.1" velocity="0.5"/>
    <parent link="torso_default"/>
    <child link="l_y_shoulder_default"/>
    <origin rpy="0 0 0" xyz="0 0.17600000000000002 0"/>
  </joint>
  <link name="l_p_shoulder_default">
        </link>
  <joint name="l_p_shoulder_default" type="revolute">
    <axis xyz="1 0 0"/>
    <limit effort="1000" lower="-0.4" upper="3.3" velocity="0.5"/>
    <parent link="l_y_shoulder_default"/>
    <child link="l_p_shoulder_default"/>
    <origin rpy="0 0 0" xyz="0 0 0"/>
  </joint>
  <link name="l_shoulder_default">
    <visual>
      <geometry>
        <cylinder length="0.35200000000000004" radius="0.03"/>
      </geometry>
      <material name="yellow-skin"/>
      <origin rpy="-1.54 0 -1.54" xyz="0 0 -0.17600000000000002"/>
    </visual>
    <visual>
      <geometry>
        <sphere radius="0.03"/>
      </geometry>
      <material name="yellow-skin"/>
      <origin rpy="0 0 0" xyz="0 0 -0.35200000000000004"/>
    </visual>
  </link>
  <joint name="l_r_shoulder_default" type="revolute">
    <axis xyz="0 0 1"/>
    <limit effort="1000" lower="-1.7" upper="1.5" velocity="0.5"/>
    <parent link="l_p_shoulder_default"/>
    <child link="l_shoulder_default"/>
    <origin rpy="0 0 0" xyz="0 0 0"/>
  </joint>
  <link name="l_elbow_default">
    <visual>
      <geometry>
        <cylinder length="0.22" radius="0.03"/>
      </geometry>
      <material name="yellow-skin"/>
      <origin rpy="-1.54 0 -1.54" xyz="0 0 -0.11"/>
    </visual>
    <visual>
      <geometry>
        <sphere radius="0.03"/>
      </geometry>
      <material name="yellow-skin"/>
      <origin rpy="0 0 0" xyz="0 0 -0.22"/>
    </visual>
  </link>
  <joint name="l_elbow_default" type="revolute">
    <axis xyz="0 -1 0"/>
    <limit effort="1000" lower="0" upper="2.5" velocity="0.5"/>
    <parent link="l_shoulder_default"/>
    <child link="l_elbow_default"/>
    <origin rpy="0 0 0" xyz="0 0 -0.35200000000000004"/>
  </joint>
  <link name="l_wrist_default">
        </link>
  <joint name="l_wrist_default" type="fixed">
    <parent link="l_elbow_default"/>
    <child link="l_wrist_default"/>
    <origin rpy="0 0 0" xyz="0 0 -0.22"/>
  </joint>
  <link name="r_y_shoulder_default">
    <visual>
      <geometry>
        <sphere radius="0.03"/>
      </geometry>
      <material name="yellow-skin-dark"/>
      <origin rpy="0 0 0" xyz="0 0 0"/>
    </visual>
  </link>
  <joint name="r_y_shoulder_default" type="revolute">
    <axis xyz="0 0 1"/>
    <limit effort="1000" lower="-1.7" upper="1.1" velocity="0.5"/>
    <parent link="torso_default"/>
    <child link="r_y_shoulder_default"/>
    <origin rpy="0 0 0" xyz="0 -0.17600000000000002 0"/>
  </joint>
  <link name="r_p_shoulder_default">
        </link>
  <joint name="r_p_shoulder_default" type="revolute">
    <axis xyz="-1 0 0"/>
    <limit effort="1000" lower="-0.4" upper="3.3" velocity="0.5"/>
    <parent link="r_y_shoulder_default"/>
    <child link="r_p_shoulder_default"/>
    <origin rpy="0 0 0" xyz="0 0 0"/>
  </joint>
  <link name="r_shoulder_default">
    <visual>
      <geometry>
        <cylinder length="0.35200000000000004" radius="0.03"/>
      </geometry>
      <material name="yellow-skin"/>
      <origin rpy="-1.54 0 -1.54" xyz="0 0 -0.17600000000000002"/>
    </visual>
    <visual>
      <geometry>
        <sphere radius="0.03"/>
      </geometry>
      <material name="yellow-skin"/>
      <origin rpy="0 0 0" xyz="0 0 -0.35200000000000004"/>
    </visual>
  </link>
  <joint name="r_r_shoulder_default" type="revolute">
    <axis xyz="0 0 -1"/>
    <limit effort="1000" lower="-1.7" upper="1.5" velocity="0.5"/>
    <parent link="r_p_shoulder_default"/>
    <child link="r_shoulder_default"/>
    <origin rpy="0 0 0" xyz="0 0 0"/>
  </joint>
  <link name="r_elbow_default">
    <visual>
      <geometry>
        <cylinder length="0.22" radius="0.03"/>
      </geometry>
      <material name="yellow-skin"/>
      <origin rpy="-1.54 0 -1.54" xyz="0 0 -0.11"/>
    </visual>
    <visual>
      <geometry>
        <sphere radius="0.03"/>
      </geometry>
      <material name="yellow-skin"/>
      <origin rpy="0 0 0" xyz="0 0 -0.22"/>
    </visual>
  </link>
  <joint name="r_elbow_default" type="revolute">
    <axis xyz="0 -1 0"/>
    <limit effort="1000" lower="0" upper="2.5" velocity="0.5"/>
    <parent link="r_shoulder_default"/>
    <child link="r_elbow_default"/>
    <origin rpy="0 0 0" xyz="0 0 -0.35200000000000004"/>
  </joint>
  <link name="r_wrist_default">
        </link>
  <joint name="r_wrist_default" type="fixed">
    <parent link="r_elbow_default"/>
    <child link="r_wrist_default"/>
    <origin rpy="0 0 0" xyz="0 0 -0.22"/>
  </joint>
  <link name="l_y_hip_default">
    <visual>
      <geometry>
        <sphere radius="0.03"/>
      </geometry>
      <material name="yellow-skin-dark"/>
      <origin rpy="0 0 0" xyz="0 0 0"/>
    </visual>
  </link>
  <joint name="l_y_hip_default" type="revolute">
    <axis xyz="0 0 -1"/>
    <limit effort="1000" lower="-.1" upper="0.6" velocity="0.5"/>
    <parent link="body_default"/>
    <child link="l_y_hip_default"/>
    <origin rpy="0 0 0" xyz="0 0.132 0"/>
  </joint>
  <link name="l_p_hip_default">
        </link>
  <joint name="l_p_hip_default" type="revolute">
    <axis xyz="1 0 0"/>
    <limit effort="1000" lower="-0.4" upper="3.3" velocity="0.5"/>
    <parent link="l_y_hip_default"/>
    <child link="l_p_hip_default"/>
    <origin rpy="0 0 0" xyz="0 0 0"/>
  </joint>
  <link name="l_hip_default">
    <visual>
      <geometry>
        <cylinder length="0.33" radius="0.03"/>
      </geometry>
      <material name="yellow-skin"/>
      <origin rpy="-1.54 0 -1.54" xyz="0 0 -0.165"/>
    </visual>
    <visual>
      <geometry>
        <sphere radius="0.03"/>
      </geometry>
      <material name="yellow-skin"/>
      <origin rpy="0 0 0" xyz="0 0 -0.33"/>
    </visual>
  </link>
  <joint name="l_r_hip_default" type="revolute">
    <axis xyz="0 -1 0"/>
    <limit effort="1000" lower="-0.4" upper="0.7" velocity="0.5"/>
    <parent link="l_p_hip_default"/>
    <child link="l_hip_default"/>
    <origin rpy="0 0 0" xyz="0 0 0"/>
  </joint>
  <link name="l_knee_default">
    <visual>
      <geometry>
        <cylinder length="0.44" radius="0.03"/>
      </geometry>
      <material name="yellow-skin"/>
      <origin rpy="-1.54 0 -1.54" xyz="0 0 -0.22"/>
    </visual>
    <visual>
      <geometry>
        <sphere radius="0.03"/>
      </geometry>
      <material name="yellow-skin"/>
      <origin rpy="0 0 0" xyz="0 0 -0.44"/>
    </visual>
  </link>
  <joint name="l_knee_default" type="revolute">
    <axis xyz="0 -1 0"/>
    <limit effort="1000" lower="-2.5" upper="0" velocity="0.5"/>
    <parent link="l_hip_default"/>
    <child link="l_knee_default"/>
    <origin rpy="0 0 0" xyz="0 0 -0.33"/>
  </joint>
  <link name="l_ankle_default">
        </link>
  <joint name="l_ankle_default" type="fixed">
    <parent link="l_knee_default"/>
    <child link="l_ankle_default"/>
    <origin rpy="0 0 0" xyz="0 0 -0.44"/>
  </joint>
  <link name="r_y_hip_default">
    <visual>
      <geometry>
        <sphere radius="0.03"/>
      </geometry>
      <material name="yellow-skin-dark"/>
      <origin rpy="0 0 0" xyz="0 0 0"/>
    </visual>
  </link>
  <joint name="r_y_hip_default" type="revolute">
    <axis xyz="0 0 -1"/>
    <limit effort="1000" lower="-.1" upper="0.6" velocity="0.5"/>
    <parent link="body_default"/>
    <child link="r_y_hip_default"/>
    <origin rpy="0 0 0" xyz="0 -0.132 0"/>
  </joint>
  <link name="r_p_hip_default">
        </link>
  <joint name="r_p_hip_default" type="revolute">
    <axis xyz="-1 0 0"/>
    <limit effort="1000" lower="-0.4" upper="3.3" velocity="0.5"/>
    <parent link="r_y_hip_default"/>
    <child link="r_p_hip_default"/>
    <origin rpy="0 0 0" xyz="0 0 0"/>
  </joint>
  <link name="r_hip_default">
    <visual>
      <geometry>
        <cylinder length="0.33" radius="0.03"/>
      </geometry>
      <material name="yellow-skin"/>
      <origin rpy="-1.54 0 -1.54" xyz="0 0 -0.165"/>
    </visual>
    <visual>
      <geometry>
        <sphere radius="0.03"/>
      </geometry>
      <material name="yellow-skin"/>
      <origin rpy="0 0 0" xyz="0 0 -0.33"/>
    </visual>
  </link>
  <joint name="r_r_hip_default" type="revolute">
    <axis xyz="0 -1 0"/>
    <limit effort="1000" lower="-0.4" upper="0.7" velocity="0.5"/>
    <parent link="r_p_hip_default"/>
    <child link="r_hip_default"/>
    <origin rpy="0 0 0" xyz="0 0 0"/>
  </joint>
  <link name="r_knee_default">
    <visual>
      <geometry>
        <cylinder length="0.44" radius="0.03"/>
      </geometry>
      <material name="yellow-skin"/>
      <origin rpy="-1.54 0 -1.54" xyz="0 0 -0.22"/>
    </visual>
    <visual>
      <geometry>
        <sphere radius="0.03"/>
      </geometry>
      <material name="yellow-skin"/>
      <origin rpy="0 0 0" xyz="0 0 -0.44"/>
    </visual>
  </link>
  <joint name="r_knee_default" type="revolute">
    <axis xyz="0 -1 0"/>
    <limit effort="1000" lower="-2.5" upper="0" velocity="0.5"/>
    <parent link="r_hip_default"/>
    <child link="r_knee_default"/>
    <origin rpy="0 0 0" xyz="0 0 -0.33"/>
  </joint>
  <link name="r_ankle_default">
        </link>
  <joint name="r_ankle_default" type="fixed">
    <parent link="r_knee_default"/>
    <child link="r_ankle_default"/>
    <origin rpy="0 0 0" xyz="0 0 -0.44"/>
  </joint>
</robot>
